2024-10-23 22:08:12 ERROR 400 response executing GraphQL.
2024-10-23 22:08:12 ERROR {"errors":[{"message":"name required for project query","path":["project"]}],"data":{"project":null}}
2024-10-23 22:08:12 ERROR Traceback (most recent call last):
  File "C:\Users\pimde\anaconda3\envs\2AMM20\Lib\site-packages\wandb\apis\normalize.py", line 41, in wrapper
    return func(*args, **kwargs)
           ^^^^^^^^^^^^^^^^^^^^^
  File "C:\Users\pimde\anaconda3\envs\2AMM20\Lib\site-packages\wandb\sdk\internal\internal_api.py", line 1055, in sweep
    response = self.gql(
               ^^^^^^^^^
  File "C:\Users\pimde\anaconda3\envs\2AMM20\Lib\site-packages\wandb\sdk\internal\internal_api.py", line 341, in gql
    ret = self._retry_gql(
          ^^^^^^^^^^^^^^^^
  File "C:\Users\pimde\anaconda3\envs\2AMM20\Lib\site-packages\wandb\sdk\lib\retry.py", line 131, in __call__
    result = self._call_fn(*args, **kwargs)
             ^^^^^^^^^^^^^^^^^^^^^^^^^^^^^^
  File "C:\Users\pimde\anaconda3\envs\2AMM20\Lib\site-packages\wandb\sdk\internal\internal_api.py", line 369, in execute
    return self.client.execute(*args, **kwargs)  # type: ignore
           ^^^^^^^^^^^^^^^^^^^^^^^^^^^^^^^^^^^^
  File "C:\Users\pimde\anaconda3\envs\2AMM20\Lib\site-packages\wandb\vendor\gql-0.2.0\wandb_gql\client.py", line 52, in execute
    result = self._get_result(document, *args, **kwargs)
             ^^^^^^^^^^^^^^^^^^^^^^^^^^^^^^^^^^^^^^^^^^^
  File "C:\Users\pimde\anaconda3\envs\2AMM20\Lib\site-packages\wandb\vendor\gql-0.2.0\wandb_gql\client.py", line 60, in _get_result
    return self.transport.execute(document, *args, **kwargs)
           ^^^^^^^^^^^^^^^^^^^^^^^^^^^^^^^^^^^^^^^^^^^^^^^^^
  File "C:\Users\pimde\anaconda3\envs\2AMM20\Lib\site-packages\wandb\sdk\lib\gql_request.py", line 59, in execute
    request.raise_for_status()
  File "C:\Users\pimde\anaconda3\envs\2AMM20\Lib\site-packages\requests\models.py", line 1024, in raise_for_status
    raise HTTPError(http_error_msg, response=self)
requests.exceptions.HTTPError: 400 Client Error: Bad Request for url: https://api.wandb.ai/graphql

During handling of the above exception, another exception occurred:

Traceback (most recent call last):
  File "C:\Users\pimde\anaconda3\envs\2AMM20\Lib\site-packages\wandb\cli\cli.py", line 105, in wrapper
    return func(*args, **kwargs)
           ^^^^^^^^^^^^^^^^^^^^^
  File "C:\Users\pimde\anaconda3\envs\2AMM20\Lib\site-packages\wandb\cli\cli.py", line 926, in sweep
    getattr(api, "%s_sweep" % state)(sweep_id, entity=entity, project=project)
  File "C:\Users\pimde\anaconda3\envs\2AMM20\Lib\site-packages\wandb\apis\internal.py", line 141, in cancel_sweep
    return self.api.cancel_sweep(*args, **kwargs)
           ^^^^^^^^^^^^^^^^^^^^^^^^^^^^^^^^^^^^^^
  File "C:\Users\pimde\anaconda3\envs\2AMM20\Lib\site-packages\wandb\sdk\internal\internal_api.py", line 4137, in cancel_sweep
    self.set_sweep_state(
  File "C:\Users\pimde\anaconda3\envs\2AMM20\Lib\site-packages\wandb\sdk\internal\internal_api.py", line 4081, in set_sweep_state
    s = self.sweep(sweep=sweep, entity=entity, project=project, specs="{}")
        ^^^^^^^^^^^^^^^^^^^^^^^^^^^^^^^^^^^^^^^^^^^^^^^^^^^^^^^^^^^^^^^^^^^
  File "C:\Users\pimde\anaconda3\envs\2AMM20\Lib\site-packages\wandb\apis\normalize.py", line 51, in wrapper
    raise CommError(message, error)
wandb.errors.CommError: name required for project query (Error 400: Bad Request)

2024-10-23 22:09:07 ERROR 400 response executing GraphQL.
2024-10-23 22:09:07 ERROR {"errors":[{"message":"name required for project query","path":["project"]}],"data":{"project":null}}
2024-10-23 22:09:07 ERROR Traceback (most recent call last):
  File "C:\Users\pimde\anaconda3\envs\2AMM20\Lib\site-packages\wandb\apis\normalize.py", line 41, in wrapper
    return func(*args, **kwargs)
           ^^^^^^^^^^^^^^^^^^^^^
  File "C:\Users\pimde\anaconda3\envs\2AMM20\Lib\site-packages\wandb\sdk\internal\internal_api.py", line 1055, in sweep
    response = self.gql(
               ^^^^^^^^^
  File "C:\Users\pimde\anaconda3\envs\2AMM20\Lib\site-packages\wandb\sdk\internal\internal_api.py", line 341, in gql
    ret = self._retry_gql(
          ^^^^^^^^^^^^^^^^
  File "C:\Users\pimde\anaconda3\envs\2AMM20\Lib\site-packages\wandb\sdk\lib\retry.py", line 131, in __call__
    result = self._call_fn(*args, **kwargs)
             ^^^^^^^^^^^^^^^^^^^^^^^^^^^^^^
  File "C:\Users\pimde\anaconda3\envs\2AMM20\Lib\site-packages\wandb\sdk\internal\internal_api.py", line 369, in execute
    return self.client.execute(*args, **kwargs)  # type: ignore
           ^^^^^^^^^^^^^^^^^^^^^^^^^^^^^^^^^^^^
  File "C:\Users\pimde\anaconda3\envs\2AMM20\Lib\site-packages\wandb\vendor\gql-0.2.0\wandb_gql\client.py", line 52, in execute
    result = self._get_result(document, *args, **kwargs)
             ^^^^^^^^^^^^^^^^^^^^^^^^^^^^^^^^^^^^^^^^^^^
  File "C:\Users\pimde\anaconda3\envs\2AMM20\Lib\site-packages\wandb\vendor\gql-0.2.0\wandb_gql\client.py", line 60, in _get_result
    return self.transport.execute(document, *args, **kwargs)
           ^^^^^^^^^^^^^^^^^^^^^^^^^^^^^^^^^^^^^^^^^^^^^^^^^
  File "C:\Users\pimde\anaconda3\envs\2AMM20\Lib\site-packages\wandb\sdk\lib\gql_request.py", line 59, in execute
    request.raise_for_status()
  File "C:\Users\pimde\anaconda3\envs\2AMM20\Lib\site-packages\requests\models.py", line 1024, in raise_for_status
    raise HTTPError(http_error_msg, response=self)
requests.exceptions.HTTPError: 400 Client Error: Bad Request for url: https://api.wandb.ai/graphql

During handling of the above exception, another exception occurred:

Traceback (most recent call last):
  File "C:\Users\pimde\anaconda3\envs\2AMM20\Lib\site-packages\wandb\cli\cli.py", line 105, in wrapper
    return func(*args, **kwargs)
           ^^^^^^^^^^^^^^^^^^^^^
  File "C:\Users\pimde\anaconda3\envs\2AMM20\Lib\site-packages\wandb\cli\cli.py", line 926, in sweep
    getattr(api, "%s_sweep" % state)(sweep_id, entity=entity, project=project)
  File "C:\Users\pimde\anaconda3\envs\2AMM20\Lib\site-packages\wandb\apis\internal.py", line 138, in stop_sweep
    return self.api.stop_sweep(*args, **kwargs)
           ^^^^^^^^^^^^^^^^^^^^^^^^^^^^^^^^^^^^
  File "C:\Users\pimde\anaconda3\envs\2AMM20\Lib\site-packages\wandb\sdk\internal\internal_api.py", line 4126, in stop_sweep
    self.set_sweep_state(
  File "C:\Users\pimde\anaconda3\envs\2AMM20\Lib\site-packages\wandb\sdk\internal\internal_api.py", line 4081, in set_sweep_state
    s = self.sweep(sweep=sweep, entity=entity, project=project, specs="{}")
        ^^^^^^^^^^^^^^^^^^^^^^^^^^^^^^^^^^^^^^^^^^^^^^^^^^^^^^^^^^^^^^^^^^^
  File "C:\Users\pimde\anaconda3\envs\2AMM20\Lib\site-packages\wandb\apis\normalize.py", line 51, in wrapper
    raise CommError(message, error)
wandb.errors.CommError: name required for project query (Error 400: Bad Request)

2024-10-23 22:11:15 INFO Running runs: []
2024-10-23 22:11:15 INFO Agent received command: run
2024-10-23 22:11:15 INFO Agent starting run with config:
	batch_size: 8
	learning_rate: 3.7138888990771435e-05
	omega_0: 15
	shared_depth: 12
	shared_width: 256
	unique_depth: 2
	unique_width: 256
2024-10-23 22:11:15 INFO About to run command: python pretrain.py --batch_size=8 --learning_rate=3.7138888990771435e-05 --omega_0=15 --shared_depth=12 --shared_width=256 --unique_depth=2 --unique_width=256
2024-10-23 22:11:20 INFO Running runs: ['qoc1u4mh']
2024-10-23 22:19:14 INFO Running runs: []
2024-10-23 22:19:15 INFO Agent received command: run
2024-10-23 22:19:15 INFO Agent starting run with config:
	batch_size: 5
	learning_rate: 7.544624899344462e-05
2024-10-23 22:19:15 INFO About to run command: python pretrain.py --batch_size=5 --learning_rate=7.544624899344462e-05
2024-10-23 22:19:20 INFO Running runs: ['1riosksj']
2024-10-23 22:30:20 INFO Cleaning up finished run: 1riosksj
2024-10-23 22:30:20 INFO Agent received command: run
2024-10-23 22:30:20 INFO Agent starting run with config:
	batch_size: 2
	learning_rate: 6.575122923640312e-05
2024-10-23 22:30:20 INFO About to run command: python pretrain.py --batch_size=2 --learning_rate=6.575122923640312e-05
2024-10-23 22:30:25 INFO Running runs: ['ao7agdwx']
2024-10-23 22:33:32 ERROR 400 response executing GraphQL.
2024-10-23 22:33:32 ERROR {"errors":[{"message":"name required for project query","path":["project"]}],"data":{"project":null}}
2024-10-23 22:33:32 ERROR Traceback (most recent call last):
  File "C:\Users\pimde\anaconda3\envs\2AMM20\Lib\site-packages\wandb\apis\normalize.py", line 41, in wrapper
    return func(*args, **kwargs)
           ^^^^^^^^^^^^^^^^^^^^^
  File "C:\Users\pimde\anaconda3\envs\2AMM20\Lib\site-packages\wandb\sdk\internal\internal_api.py", line 1055, in sweep
    response = self.gql(
               ^^^^^^^^^
  File "C:\Users\pimde\anaconda3\envs\2AMM20\Lib\site-packages\wandb\sdk\internal\internal_api.py", line 341, in gql
    ret = self._retry_gql(
          ^^^^^^^^^^^^^^^^
  File "C:\Users\pimde\anaconda3\envs\2AMM20\Lib\site-packages\wandb\sdk\lib\retry.py", line 131, in __call__
    result = self._call_fn(*args, **kwargs)
             ^^^^^^^^^^^^^^^^^^^^^^^^^^^^^^
  File "C:\Users\pimde\anaconda3\envs\2AMM20\Lib\site-packages\wandb\sdk\internal\internal_api.py", line 369, in execute
    return self.client.execute(*args, **kwargs)  # type: ignore
           ^^^^^^^^^^^^^^^^^^^^^^^^^^^^^^^^^^^^
  File "C:\Users\pimde\anaconda3\envs\2AMM20\Lib\site-packages\wandb\vendor\gql-0.2.0\wandb_gql\client.py", line 52, in execute
    result = self._get_result(document, *args, **kwargs)
             ^^^^^^^^^^^^^^^^^^^^^^^^^^^^^^^^^^^^^^^^^^^
  File "C:\Users\pimde\anaconda3\envs\2AMM20\Lib\site-packages\wandb\vendor\gql-0.2.0\wandb_gql\client.py", line 60, in _get_result
    return self.transport.execute(document, *args, **kwargs)
           ^^^^^^^^^^^^^^^^^^^^^^^^^^^^^^^^^^^^^^^^^^^^^^^^^
  File "C:\Users\pimde\anaconda3\envs\2AMM20\Lib\site-packages\wandb\sdk\lib\gql_request.py", line 59, in execute
    request.raise_for_status()
  File "C:\Users\pimde\anaconda3\envs\2AMM20\Lib\site-packages\requests\models.py", line 1024, in raise_for_status
    raise HTTPError(http_error_msg, response=self)
requests.exceptions.HTTPError: 400 Client Error: Bad Request for url: https://api.wandb.ai/graphql

During handling of the above exception, another exception occurred:

Traceback (most recent call last):
  File "C:\Users\pimde\anaconda3\envs\2AMM20\Lib\site-packages\wandb\cli\cli.py", line 105, in wrapper
    return func(*args, **kwargs)
           ^^^^^^^^^^^^^^^^^^^^^
  File "C:\Users\pimde\anaconda3\envs\2AMM20\Lib\site-packages\wandb\cli\cli.py", line 926, in sweep
    getattr(api, "%s_sweep" % state)(sweep_id, entity=entity, project=project)
  File "C:\Users\pimde\anaconda3\envs\2AMM20\Lib\site-packages\wandb\apis\internal.py", line 141, in cancel_sweep
    return self.api.cancel_sweep(*args, **kwargs)
           ^^^^^^^^^^^^^^^^^^^^^^^^^^^^^^^^^^^^^^
  File "C:\Users\pimde\anaconda3\envs\2AMM20\Lib\site-packages\wandb\sdk\internal\internal_api.py", line 4137, in cancel_sweep
    self.set_sweep_state(
  File "C:\Users\pimde\anaconda3\envs\2AMM20\Lib\site-packages\wandb\sdk\internal\internal_api.py", line 4081, in set_sweep_state
    s = self.sweep(sweep=sweep, entity=entity, project=project, specs="{}")
        ^^^^^^^^^^^^^^^^^^^^^^^^^^^^^^^^^^^^^^^^^^^^^^^^^^^^^^^^^^^^^^^^^^^
  File "C:\Users\pimde\anaconda3\envs\2AMM20\Lib\site-packages\wandb\apis\normalize.py", line 51, in wrapper
    raise CommError(message, error)
wandb.errors.CommError: name required for project query (Error 400: Bad Request)

2024-10-23 22:34:11 ERROR Traceback (most recent call last):
  File "C:\Users\pimde\anaconda3\envs\2AMM20\Lib\site-packages\wandb\apis\normalize.py", line 41, in wrapper
    return func(*args, **kwargs)
           ^^^^^^^^^^^^^^^^^^^^^
  File "C:\Users\pimde\anaconda3\envs\2AMM20\Lib\site-packages\wandb\sdk\internal\internal_api.py", line 1065, in sweep
    raise ValueError(f"Sweep {entity}/{project}/{sweep} not found")
ValueError: Sweep None/SPO_pretrainer_sweeptest/cevzkr9s not found

During handling of the above exception, another exception occurred:

Traceback (most recent call last):
  File "C:\Users\pimde\anaconda3\envs\2AMM20\Lib\site-packages\wandb\cli\cli.py", line 105, in wrapper
    return func(*args, **kwargs)
           ^^^^^^^^^^^^^^^^^^^^^
  File "C:\Users\pimde\anaconda3\envs\2AMM20\Lib\site-packages\wandb\cli\cli.py", line 926, in sweep
    getattr(api, "%s_sweep" % state)(sweep_id, entity=entity, project=project)
  File "C:\Users\pimde\anaconda3\envs\2AMM20\Lib\site-packages\wandb\apis\internal.py", line 141, in cancel_sweep
    return self.api.cancel_sweep(*args, **kwargs)
           ^^^^^^^^^^^^^^^^^^^^^^^^^^^^^^^^^^^^^^
  File "C:\Users\pimde\anaconda3\envs\2AMM20\Lib\site-packages\wandb\sdk\internal\internal_api.py", line 4137, in cancel_sweep
    self.set_sweep_state(
  File "C:\Users\pimde\anaconda3\envs\2AMM20\Lib\site-packages\wandb\sdk\internal\internal_api.py", line 4081, in set_sweep_state
    s = self.sweep(sweep=sweep, entity=entity, project=project, specs="{}")
        ^^^^^^^^^^^^^^^^^^^^^^^^^^^^^^^^^^^^^^^^^^^^^^^^^^^^^^^^^^^^^^^^^^^
  File "C:\Users\pimde\anaconda3\envs\2AMM20\Lib\site-packages\wandb\apis\normalize.py", line 87, in wrapper
    raise CommError(message, err).with_traceback(sys.exc_info()[2])
  File "C:\Users\pimde\anaconda3\envs\2AMM20\Lib\site-packages\wandb\apis\normalize.py", line 41, in wrapper
    return func(*args, **kwargs)
           ^^^^^^^^^^^^^^^^^^^^^
  File "C:\Users\pimde\anaconda3\envs\2AMM20\Lib\site-packages\wandb\sdk\internal\internal_api.py", line 1065, in sweep
    raise ValueError(f"Sweep {entity}/{project}/{sweep} not found")
wandb.errors.CommError: Sweep None/SPO_pretrainer_sweeptest/cevzkr9s not found

