2024-10-23 22:49:00 ERROR 400 response executing GraphQL.
2024-10-23 22:49:00 ERROR {"errors":[{"message":"name required for project query","path":["project"]}],"data":{"project":null}}
2024-10-23 22:49:00 ERROR Traceback (most recent call last):
  File "/gpfs/home2/scur1981/2AMM20_NFgroup1/lib/python3.11/site-packages/wandb/apis/normalize.py", line 41, in wrapper
    return func(*args, **kwargs)
           ^^^^^^^^^^^^^^^^^^^^^
  File "/gpfs/home2/scur1981/2AMM20_NFgroup1/lib/python3.11/site-packages/wandb/sdk/internal/internal_api.py", line 1074, in sweep
    response = self.gql(
               ^^^^^^^^^
  File "/gpfs/home2/scur1981/2AMM20_NFgroup1/lib/python3.11/site-packages/wandb/sdk/internal/internal_api.py", line 326, in gql
    ret = self._retry_gql(
          ^^^^^^^^^^^^^^^^
  File "/gpfs/home2/scur1981/2AMM20_NFgroup1/lib/python3.11/site-packages/wandb/sdk/lib/retry.py", line 131, in __call__
    result = self._call_fn(*args, **kwargs)
             ^^^^^^^^^^^^^^^^^^^^^^^^^^^^^^
  File "/gpfs/home2/scur1981/2AMM20_NFgroup1/lib/python3.11/site-packages/wandb/sdk/internal/internal_api.py", line 354, in execute
    return self.client.execute(*args, **kwargs)  # type: ignore
           ^^^^^^^^^^^^^^^^^^^^^^^^^^^^^^^^^^^^
  File "/gpfs/home2/scur1981/2AMM20_NFgroup1/lib/python3.11/site-packages/wandb/vendor/gql-0.2.0/wandb_gql/client.py", line 52, in execute
    result = self._get_result(document, *args, **kwargs)
             ^^^^^^^^^^^^^^^^^^^^^^^^^^^^^^^^^^^^^^^^^^^
  File "/gpfs/home2/scur1981/2AMM20_NFgroup1/lib/python3.11/site-packages/wandb/vendor/gql-0.2.0/wandb_gql/client.py", line 60, in _get_result
    return self.transport.execute(document, *args, **kwargs)
           ^^^^^^^^^^^^^^^^^^^^^^^^^^^^^^^^^^^^^^^^^^^^^^^^^
  File "/gpfs/home2/scur1981/2AMM20_NFgroup1/lib/python3.11/site-packages/wandb/sdk/lib/gql_request.py", line 59, in execute
    request.raise_for_status()
  File "/sw/arch/RHEL8/EB_production/2023/software/poetry/1.5.1-GCCcore-12.3.0/lib/python3.11/site-packages/requests/models.py", line 1021, in raise_for_status
    raise HTTPError(http_error_msg, response=self)
requests.exceptions.HTTPError: 400 Client Error: Bad Request for url: https://api.wandb.ai/graphql

During handling of the above exception, another exception occurred:

Traceback (most recent call last):
  File "/gpfs/home2/scur1981/2AMM20_NFgroup1/lib/python3.11/site-packages/wandb/cli/cli.py", line 103, in wrapper
    return func(*args, **kwargs)
           ^^^^^^^^^^^^^^^^^^^^^
  File "/gpfs/home2/scur1981/2AMM20_NFgroup1/lib/python3.11/site-packages/wandb/cli/cli.py", line 1677, in agent
    wandb_agent.agent(sweep_id, entity=entity, project=project, count=count)
  File "/gpfs/home2/scur1981/2AMM20_NFgroup1/lib/python3.11/site-packages/wandb/wandb_agent.py", line 572, in agent
    return run_agent(
           ^^^^^^^^^^
  File "/gpfs/home2/scur1981/2AMM20_NFgroup1/lib/python3.11/site-packages/wandb/wandb_agent.py", line 530, in run_agent
    agent.run()
  File "/gpfs/home2/scur1981/2AMM20_NFgroup1/lib/python3.11/site-packages/wandb/wandb_agent.py", line 192, in run
    sweep_obj = self._api.sweep(self._sweep_id, "{}")
                ^^^^^^^^^^^^^^^^^^^^^^^^^^^^^^^^^^^^^
  File "/gpfs/home2/scur1981/2AMM20_NFgroup1/lib/python3.11/site-packages/wandb/apis/internal.py", line 130, in sweep
    return self.api.sweep(*args, **kwargs)
           ^^^^^^^^^^^^^^^^^^^^^^^^^^^^^^^
  File "/gpfs/home2/scur1981/2AMM20_NFgroup1/lib/python3.11/site-packages/wandb/apis/normalize.py", line 51, in wrapper
    raise CommError(message, error)
wandb.errors.errors.CommError: name required for project query (Error 400: Bad Request)

2024-10-23 23:19:29 ERROR Traceback (most recent call last):
  File "/gpfs/home2/scur1981/2AMM20_NFgroup1/lib/python3.11/site-packages/wandb/apis/normalize.py", line 41, in wrapper
    return func(*args, **kwargs)
           ^^^^^^^^^^^^^^^^^^^^^
  File "/gpfs/home2/scur1981/2AMM20_NFgroup1/lib/python3.11/site-packages/wandb/sdk/internal/internal_api.py", line 1084, in sweep
    raise ValueError(f"Sweep {entity}/{project}/{sweep} not found")
ValueError: Sweep my_entity/my_project/my_entity/my_project/ not found

During handling of the above exception, another exception occurred:

Traceback (most recent call last):
  File "/gpfs/home2/scur1981/2AMM20_NFgroup1/lib/python3.11/site-packages/wandb/cli/cli.py", line 103, in wrapper
    return func(*args, **kwargs)
           ^^^^^^^^^^^^^^^^^^^^^
  File "/gpfs/home2/scur1981/2AMM20_NFgroup1/lib/python3.11/site-packages/wandb/cli/cli.py", line 1677, in agent
    wandb_agent.agent(sweep_id, entity=entity, project=project, count=count)
  File "/gpfs/home2/scur1981/2AMM20_NFgroup1/lib/python3.11/site-packages/wandb/wandb_agent.py", line 572, in agent
    return run_agent(
           ^^^^^^^^^^
  File "/gpfs/home2/scur1981/2AMM20_NFgroup1/lib/python3.11/site-packages/wandb/wandb_agent.py", line 530, in run_agent
    agent.run()
  File "/gpfs/home2/scur1981/2AMM20_NFgroup1/lib/python3.11/site-packages/wandb/wandb_agent.py", line 192, in run
    sweep_obj = self._api.sweep(self._sweep_id, "{}")
                ^^^^^^^^^^^^^^^^^^^^^^^^^^^^^^^^^^^^^
  File "/gpfs/home2/scur1981/2AMM20_NFgroup1/lib/python3.11/site-packages/wandb/apis/internal.py", line 130, in sweep
    return self.api.sweep(*args, **kwargs)
           ^^^^^^^^^^^^^^^^^^^^^^^^^^^^^^^
  File "/gpfs/home2/scur1981/2AMM20_NFgroup1/lib/python3.11/site-packages/wandb/apis/normalize.py", line 87, in wrapper
    raise CommError(message, err).with_traceback(sys.exc_info()[2])
  File "/gpfs/home2/scur1981/2AMM20_NFgroup1/lib/python3.11/site-packages/wandb/apis/normalize.py", line 41, in wrapper
    return func(*args, **kwargs)
           ^^^^^^^^^^^^^^^^^^^^^
  File "/gpfs/home2/scur1981/2AMM20_NFgroup1/lib/python3.11/site-packages/wandb/sdk/internal/internal_api.py", line 1084, in sweep
    raise ValueError(f"Sweep {entity}/{project}/{sweep} not found")
wandb.errors.errors.CommError: Sweep my_entity/my_project/my_entity/my_project/ not found

2024-10-23 23:25:31 ERROR Traceback (most recent call last):
  File "/gpfs/home2/scur1981/2AMM20_NFgroup1/lib/python3.11/site-packages/wandb/apis/normalize.py", line 41, in wrapper
    return func(*args, **kwargs)
           ^^^^^^^^^^^^^^^^^^^^^
  File "/gpfs/home2/scur1981/2AMM20_NFgroup1/lib/python3.11/site-packages/wandb/sdk/internal/internal_api.py", line 1084, in sweep
    raise ValueError(f"Sweep {entity}/{project}/{sweep} not found")
ValueError: Sweep pimdewildt11-eindhoven-university-of-technology/SPO_pretrainer_SnelliusSweep/pimdewildt11-eindhoven-university-of-technology/SPO_pretrainer_SnelliusSweep/ not found

During handling of the above exception, another exception occurred:

Traceback (most recent call last):
  File "/gpfs/home2/scur1981/2AMM20_NFgroup1/lib/python3.11/site-packages/wandb/cli/cli.py", line 103, in wrapper
    return func(*args, **kwargs)
           ^^^^^^^^^^^^^^^^^^^^^
  File "/gpfs/home2/scur1981/2AMM20_NFgroup1/lib/python3.11/site-packages/wandb/cli/cli.py", line 1677, in agent
    wandb_agent.agent(sweep_id, entity=entity, project=project, count=count)
  File "/gpfs/home2/scur1981/2AMM20_NFgroup1/lib/python3.11/site-packages/wandb/wandb_agent.py", line 572, in agent
    return run_agent(
           ^^^^^^^^^^
  File "/gpfs/home2/scur1981/2AMM20_NFgroup1/lib/python3.11/site-packages/wandb/wandb_agent.py", line 530, in run_agent
    agent.run()
  File "/gpfs/home2/scur1981/2AMM20_NFgroup1/lib/python3.11/site-packages/wandb/wandb_agent.py", line 192, in run
    sweep_obj = self._api.sweep(self._sweep_id, "{}")
                ^^^^^^^^^^^^^^^^^^^^^^^^^^^^^^^^^^^^^
  File "/gpfs/home2/scur1981/2AMM20_NFgroup1/lib/python3.11/site-packages/wandb/apis/internal.py", line 130, in sweep
    return self.api.sweep(*args, **kwargs)
           ^^^^^^^^^^^^^^^^^^^^^^^^^^^^^^^
  File "/gpfs/home2/scur1981/2AMM20_NFgroup1/lib/python3.11/site-packages/wandb/apis/normalize.py", line 87, in wrapper
    raise CommError(message, err).with_traceback(sys.exc_info()[2])
  File "/gpfs/home2/scur1981/2AMM20_NFgroup1/lib/python3.11/site-packages/wandb/apis/normalize.py", line 41, in wrapper
    return func(*args, **kwargs)
           ^^^^^^^^^^^^^^^^^^^^^
  File "/gpfs/home2/scur1981/2AMM20_NFgroup1/lib/python3.11/site-packages/wandb/sdk/internal/internal_api.py", line 1084, in sweep
    raise ValueError(f"Sweep {entity}/{project}/{sweep} not found")
wandb.errors.errors.CommError: Sweep pimdewildt11-eindhoven-university-of-technology/SPO_pretrainer_SnelliusSweep/pimdewildt11-eindhoven-university-of-technology/SPO_pretrainer_SnelliusSweep/ not found

2024-10-23 23:28:33 ERROR 400 response executing GraphQL.
2024-10-23 23:28:33 ERROR {"errors":[{"message":"name required for project query","path":["project"]}],"data":{"project":null}}
2024-10-23 23:28:33 ERROR Traceback (most recent call last):
  File "/gpfs/home2/scur1981/2AMM20_NFgroup1/lib/python3.11/site-packages/wandb/apis/normalize.py", line 41, in wrapper
    return func(*args, **kwargs)
           ^^^^^^^^^^^^^^^^^^^^^
  File "/gpfs/home2/scur1981/2AMM20_NFgroup1/lib/python3.11/site-packages/wandb/sdk/internal/internal_api.py", line 1074, in sweep
    response = self.gql(
               ^^^^^^^^^
  File "/gpfs/home2/scur1981/2AMM20_NFgroup1/lib/python3.11/site-packages/wandb/sdk/internal/internal_api.py", line 326, in gql
    ret = self._retry_gql(
          ^^^^^^^^^^^^^^^^
  File "/gpfs/home2/scur1981/2AMM20_NFgroup1/lib/python3.11/site-packages/wandb/sdk/lib/retry.py", line 131, in __call__
    result = self._call_fn(*args, **kwargs)
             ^^^^^^^^^^^^^^^^^^^^^^^^^^^^^^
  File "/gpfs/home2/scur1981/2AMM20_NFgroup1/lib/python3.11/site-packages/wandb/sdk/internal/internal_api.py", line 354, in execute
    return self.client.execute(*args, **kwargs)  # type: ignore
           ^^^^^^^^^^^^^^^^^^^^^^^^^^^^^^^^^^^^
  File "/gpfs/home2/scur1981/2AMM20_NFgroup1/lib/python3.11/site-packages/wandb/vendor/gql-0.2.0/wandb_gql/client.py", line 52, in execute
    result = self._get_result(document, *args, **kwargs)
             ^^^^^^^^^^^^^^^^^^^^^^^^^^^^^^^^^^^^^^^^^^^
  File "/gpfs/home2/scur1981/2AMM20_NFgroup1/lib/python3.11/site-packages/wandb/vendor/gql-0.2.0/wandb_gql/client.py", line 60, in _get_result
    return self.transport.execute(document, *args, **kwargs)
           ^^^^^^^^^^^^^^^^^^^^^^^^^^^^^^^^^^^^^^^^^^^^^^^^^
  File "/gpfs/home2/scur1981/2AMM20_NFgroup1/lib/python3.11/site-packages/wandb/sdk/lib/gql_request.py", line 59, in execute
    request.raise_for_status()
  File "/sw/arch/RHEL8/EB_production/2023/software/poetry/1.5.1-GCCcore-12.3.0/lib/python3.11/site-packages/requests/models.py", line 1021, in raise_for_status
    raise HTTPError(http_error_msg, response=self)
requests.exceptions.HTTPError: 400 Client Error: Bad Request for url: https://api.wandb.ai/graphql

During handling of the above exception, another exception occurred:

Traceback (most recent call last):
  File "/gpfs/home2/scur1981/2AMM20_NFgroup1/lib/python3.11/site-packages/wandb/cli/cli.py", line 103, in wrapper
    return func(*args, **kwargs)
           ^^^^^^^^^^^^^^^^^^^^^
  File "/gpfs/home2/scur1981/2AMM20_NFgroup1/lib/python3.11/site-packages/wandb/cli/cli.py", line 1677, in agent
    wandb_agent.agent(sweep_id, entity=entity, project=project, count=count)
  File "/gpfs/home2/scur1981/2AMM20_NFgroup1/lib/python3.11/site-packages/wandb/wandb_agent.py", line 572, in agent
    return run_agent(
           ^^^^^^^^^^
  File "/gpfs/home2/scur1981/2AMM20_NFgroup1/lib/python3.11/site-packages/wandb/wandb_agent.py", line 530, in run_agent
    agent.run()
  File "/gpfs/home2/scur1981/2AMM20_NFgroup1/lib/python3.11/site-packages/wandb/wandb_agent.py", line 192, in run
    sweep_obj = self._api.sweep(self._sweep_id, "{}")
                ^^^^^^^^^^^^^^^^^^^^^^^^^^^^^^^^^^^^^
  File "/gpfs/home2/scur1981/2AMM20_NFgroup1/lib/python3.11/site-packages/wandb/apis/internal.py", line 130, in sweep
    return self.api.sweep(*args, **kwargs)
           ^^^^^^^^^^^^^^^^^^^^^^^^^^^^^^^
  File "/gpfs/home2/scur1981/2AMM20_NFgroup1/lib/python3.11/site-packages/wandb/apis/normalize.py", line 51, in wrapper
    raise CommError(message, error)
wandb.errors.errors.CommError: name required for project query (Error 400: Bad Request)

2024-10-23 23:34:32 ERROR Traceback (most recent call last):
  File "/gpfs/home2/scur1981/2AMM20_NFgroup1/lib/python3.11/site-packages/wandb/apis/normalize.py", line 41, in wrapper
    return func(*args, **kwargs)
           ^^^^^^^^^^^^^^^^^^^^^
  File "/gpfs/home2/scur1981/2AMM20_NFgroup1/lib/python3.11/site-packages/wandb/sdk/internal/internal_api.py", line 1084, in sweep
    raise ValueError(f"Sweep {entity}/{project}/{sweep} not found")
ValueError: Sweep my_entity/my_project/my_entity/my_project/ not found

During handling of the above exception, another exception occurred:

Traceback (most recent call last):
  File "/gpfs/home2/scur1981/2AMM20_NFgroup1/lib/python3.11/site-packages/wandb/cli/cli.py", line 103, in wrapper
    return func(*args, **kwargs)
           ^^^^^^^^^^^^^^^^^^^^^
  File "/gpfs/home2/scur1981/2AMM20_NFgroup1/lib/python3.11/site-packages/wandb/cli/cli.py", line 1677, in agent
    wandb_agent.agent(sweep_id, entity=entity, project=project, count=count)
  File "/gpfs/home2/scur1981/2AMM20_NFgroup1/lib/python3.11/site-packages/wandb/wandb_agent.py", line 572, in agent
    return run_agent(
           ^^^^^^^^^^
  File "/gpfs/home2/scur1981/2AMM20_NFgroup1/lib/python3.11/site-packages/wandb/wandb_agent.py", line 530, in run_agent
    agent.run()
  File "/gpfs/home2/scur1981/2AMM20_NFgroup1/lib/python3.11/site-packages/wandb/wandb_agent.py", line 192, in run
    sweep_obj = self._api.sweep(self._sweep_id, "{}")
                ^^^^^^^^^^^^^^^^^^^^^^^^^^^^^^^^^^^^^
  File "/gpfs/home2/scur1981/2AMM20_NFgroup1/lib/python3.11/site-packages/wandb/apis/internal.py", line 130, in sweep
    return self.api.sweep(*args, **kwargs)
           ^^^^^^^^^^^^^^^^^^^^^^^^^^^^^^^
  File "/gpfs/home2/scur1981/2AMM20_NFgroup1/lib/python3.11/site-packages/wandb/apis/normalize.py", line 87, in wrapper
    raise CommError(message, err).with_traceback(sys.exc_info()[2])
  File "/gpfs/home2/scur1981/2AMM20_NFgroup1/lib/python3.11/site-packages/wandb/apis/normalize.py", line 41, in wrapper
    return func(*args, **kwargs)
           ^^^^^^^^^^^^^^^^^^^^^
  File "/gpfs/home2/scur1981/2AMM20_NFgroup1/lib/python3.11/site-packages/wandb/sdk/internal/internal_api.py", line 1084, in sweep
    raise ValueError(f"Sweep {entity}/{project}/{sweep} not found")
wandb.errors.errors.CommError: Sweep my_entity/my_project/my_entity/my_project/ not found

2024-10-23 23:36:32 ERROR 400 response executing GraphQL.
2024-10-23 23:36:32 ERROR {"errors":[{"message":"name required for project query","path":["project"]}],"data":{"project":null}}
2024-10-23 23:36:32 ERROR Traceback (most recent call last):
  File "/gpfs/home2/scur1981/2AMM20_NFgroup1/lib/python3.11/site-packages/wandb/apis/normalize.py", line 41, in wrapper
    return func(*args, **kwargs)
           ^^^^^^^^^^^^^^^^^^^^^
  File "/gpfs/home2/scur1981/2AMM20_NFgroup1/lib/python3.11/site-packages/wandb/sdk/internal/internal_api.py", line 1074, in sweep
    response = self.gql(
               ^^^^^^^^^
  File "/gpfs/home2/scur1981/2AMM20_NFgroup1/lib/python3.11/site-packages/wandb/sdk/internal/internal_api.py", line 326, in gql
    ret = self._retry_gql(
          ^^^^^^^^^^^^^^^^
  File "/gpfs/home2/scur1981/2AMM20_NFgroup1/lib/python3.11/site-packages/wandb/sdk/lib/retry.py", line 131, in __call__
    result = self._call_fn(*args, **kwargs)
             ^^^^^^^^^^^^^^^^^^^^^^^^^^^^^^
  File "/gpfs/home2/scur1981/2AMM20_NFgroup1/lib/python3.11/site-packages/wandb/sdk/internal/internal_api.py", line 354, in execute
    return self.client.execute(*args, **kwargs)  # type: ignore
           ^^^^^^^^^^^^^^^^^^^^^^^^^^^^^^^^^^^^
  File "/gpfs/home2/scur1981/2AMM20_NFgroup1/lib/python3.11/site-packages/wandb/vendor/gql-0.2.0/wandb_gql/client.py", line 52, in execute
    result = self._get_result(document, *args, **kwargs)
             ^^^^^^^^^^^^^^^^^^^^^^^^^^^^^^^^^^^^^^^^^^^
  File "/gpfs/home2/scur1981/2AMM20_NFgroup1/lib/python3.11/site-packages/wandb/vendor/gql-0.2.0/wandb_gql/client.py", line 60, in _get_result
    return self.transport.execute(document, *args, **kwargs)
           ^^^^^^^^^^^^^^^^^^^^^^^^^^^^^^^^^^^^^^^^^^^^^^^^^
  File "/gpfs/home2/scur1981/2AMM20_NFgroup1/lib/python3.11/site-packages/wandb/sdk/lib/gql_request.py", line 59, in execute
    request.raise_for_status()
  File "/sw/arch/RHEL8/EB_production/2023/software/poetry/1.5.1-GCCcore-12.3.0/lib/python3.11/site-packages/requests/models.py", line 1021, in raise_for_status
    raise HTTPError(http_error_msg, response=self)
requests.exceptions.HTTPError: 400 Client Error: Bad Request for url: https://api.wandb.ai/graphql

During handling of the above exception, another exception occurred:

Traceback (most recent call last):
  File "/gpfs/home2/scur1981/2AMM20_NFgroup1/lib/python3.11/site-packages/wandb/cli/cli.py", line 103, in wrapper
    return func(*args, **kwargs)
           ^^^^^^^^^^^^^^^^^^^^^
  File "/gpfs/home2/scur1981/2AMM20_NFgroup1/lib/python3.11/site-packages/wandb/cli/cli.py", line 1677, in agent
    wandb_agent.agent(sweep_id, entity=entity, project=project, count=count)
  File "/gpfs/home2/scur1981/2AMM20_NFgroup1/lib/python3.11/site-packages/wandb/wandb_agent.py", line 572, in agent
    return run_agent(
           ^^^^^^^^^^
  File "/gpfs/home2/scur1981/2AMM20_NFgroup1/lib/python3.11/site-packages/wandb/wandb_agent.py", line 530, in run_agent
    agent.run()
  File "/gpfs/home2/scur1981/2AMM20_NFgroup1/lib/python3.11/site-packages/wandb/wandb_agent.py", line 192, in run
    sweep_obj = self._api.sweep(self._sweep_id, "{}")
                ^^^^^^^^^^^^^^^^^^^^^^^^^^^^^^^^^^^^^
  File "/gpfs/home2/scur1981/2AMM20_NFgroup1/lib/python3.11/site-packages/wandb/apis/internal.py", line 130, in sweep
    return self.api.sweep(*args, **kwargs)
           ^^^^^^^^^^^^^^^^^^^^^^^^^^^^^^^
  File "/gpfs/home2/scur1981/2AMM20_NFgroup1/lib/python3.11/site-packages/wandb/apis/normalize.py", line 51, in wrapper
    raise CommError(message, error)
wandb.errors.errors.CommError: name required for project query (Error 400: Bad Request)

2024-10-23 23:37:32 ERROR 400 response executing GraphQL.
2024-10-23 23:37:32 ERROR {"errors":[{"message":"name required for project query","path":["project"]}],"data":{"project":null}}
2024-10-23 23:37:32 ERROR Traceback (most recent call last):
  File "/gpfs/home2/scur1981/2AMM20_NFgroup1/lib/python3.11/site-packages/wandb/apis/normalize.py", line 41, in wrapper
    return func(*args, **kwargs)
           ^^^^^^^^^^^^^^^^^^^^^
  File "/gpfs/home2/scur1981/2AMM20_NFgroup1/lib/python3.11/site-packages/wandb/sdk/internal/internal_api.py", line 1074, in sweep
    response = self.gql(
               ^^^^^^^^^
  File "/gpfs/home2/scur1981/2AMM20_NFgroup1/lib/python3.11/site-packages/wandb/sdk/internal/internal_api.py", line 326, in gql
    ret = self._retry_gql(
          ^^^^^^^^^^^^^^^^
  File "/gpfs/home2/scur1981/2AMM20_NFgroup1/lib/python3.11/site-packages/wandb/sdk/lib/retry.py", line 131, in __call__
    result = self._call_fn(*args, **kwargs)
             ^^^^^^^^^^^^^^^^^^^^^^^^^^^^^^
  File "/gpfs/home2/scur1981/2AMM20_NFgroup1/lib/python3.11/site-packages/wandb/sdk/internal/internal_api.py", line 354, in execute
    return self.client.execute(*args, **kwargs)  # type: ignore
           ^^^^^^^^^^^^^^^^^^^^^^^^^^^^^^^^^^^^
  File "/gpfs/home2/scur1981/2AMM20_NFgroup1/lib/python3.11/site-packages/wandb/vendor/gql-0.2.0/wandb_gql/client.py", line 52, in execute
    result = self._get_result(document, *args, **kwargs)
             ^^^^^^^^^^^^^^^^^^^^^^^^^^^^^^^^^^^^^^^^^^^
  File "/gpfs/home2/scur1981/2AMM20_NFgroup1/lib/python3.11/site-packages/wandb/vendor/gql-0.2.0/wandb_gql/client.py", line 60, in _get_result
    return self.transport.execute(document, *args, **kwargs)
           ^^^^^^^^^^^^^^^^^^^^^^^^^^^^^^^^^^^^^^^^^^^^^^^^^
  File "/gpfs/home2/scur1981/2AMM20_NFgroup1/lib/python3.11/site-packages/wandb/sdk/lib/gql_request.py", line 59, in execute
    request.raise_for_status()
  File "/sw/arch/RHEL8/EB_production/2023/software/poetry/1.5.1-GCCcore-12.3.0/lib/python3.11/site-packages/requests/models.py", line 1021, in raise_for_status
    raise HTTPError(http_error_msg, response=self)
requests.exceptions.HTTPError: 400 Client Error: Bad Request for url: https://api.wandb.ai/graphql

During handling of the above exception, another exception occurred:

Traceback (most recent call last):
  File "/gpfs/home2/scur1981/2AMM20_NFgroup1/lib/python3.11/site-packages/wandb/cli/cli.py", line 103, in wrapper
    return func(*args, **kwargs)
           ^^^^^^^^^^^^^^^^^^^^^
  File "/gpfs/home2/scur1981/2AMM20_NFgroup1/lib/python3.11/site-packages/wandb/cli/cli.py", line 1677, in agent
    wandb_agent.agent(sweep_id, entity=entity, project=project, count=count)
  File "/gpfs/home2/scur1981/2AMM20_NFgroup1/lib/python3.11/site-packages/wandb/wandb_agent.py", line 572, in agent
    return run_agent(
           ^^^^^^^^^^
  File "/gpfs/home2/scur1981/2AMM20_NFgroup1/lib/python3.11/site-packages/wandb/wandb_agent.py", line 530, in run_agent
    agent.run()
  File "/gpfs/home2/scur1981/2AMM20_NFgroup1/lib/python3.11/site-packages/wandb/wandb_agent.py", line 192, in run
    sweep_obj = self._api.sweep(self._sweep_id, "{}")
                ^^^^^^^^^^^^^^^^^^^^^^^^^^^^^^^^^^^^^
  File "/gpfs/home2/scur1981/2AMM20_NFgroup1/lib/python3.11/site-packages/wandb/apis/internal.py", line 130, in sweep
    return self.api.sweep(*args, **kwargs)
           ^^^^^^^^^^^^^^^^^^^^^^^^^^^^^^^
  File "/gpfs/home2/scur1981/2AMM20_NFgroup1/lib/python3.11/site-packages/wandb/apis/normalize.py", line 51, in wrapper
    raise CommError(message, error)
wandb.errors.errors.CommError: name required for project query (Error 400: Bad Request)

2024-10-23 23:45:06 INFO Running runs: []
2024-10-23 23:45:06 INFO Agent received command: run
2024-10-23 23:45:06 INFO Agent starting run with config:
	batch_size: 75
	learning_rate: 3.1865516887557035e-05
	omega_0: 51
	shared_depth: 12
	shared_width: 256
	unique_depth: 2
	unique_width: 128
2024-10-23 23:45:06 INFO About to run command: /usr/bin/env python pretrain.py --batch_size=75 --learning_rate=3.1865516887557035e-05 --omega_0=51 --shared_depth=12 --shared_width=256 --unique_depth=2 --unique_width=128
2024-10-23 23:45:11 INFO Running runs: ['shbcny7b']
2024-10-23 23:45:27 INFO Cleaning up finished run: shbcny7b
2024-10-23 23:45:27 INFO Agent received command: run
2024-10-23 23:45:27 INFO Agent starting run with config:
	batch_size: 25
	learning_rate: 9.547814859238038e-05
	omega_0: 30
	shared_depth: 6
	shared_width: 256
	unique_depth: 2
	unique_width: 128
2024-10-23 23:45:27 INFO About to run command: /usr/bin/env python pretrain.py --batch_size=25 --learning_rate=9.547814859238038e-05 --omega_0=30 --shared_depth=6 --shared_width=256 --unique_depth=2 --unique_width=128
2024-10-23 23:45:32 INFO Running runs: ['wzqbhxik']
2024-10-23 23:46:14 ERROR 404 response executing GraphQL.
2024-10-23 23:46:14 ERROR {"errors":[{"message":"could not find agent ee5rsu9v during agentHeartbeat","path":["agentHeartbeat"]}],"data":{"agentHeartbeat":null}}
